Workbook

Sheet Summary
A1: SmartCiti.X ~ Holodeck — investor data pack
A2: Every figure below is a formula over the data sheets, which the repository's own generator (tools/gen_investor.mjs) writes from the catalog, the eval report and the world data. No revenue, price, market or user figure appears anywhere.
A3: Measure | B3: Value | C3: Where it comes from
A4: Content
A5: Graded procedures | B5: =COUNTA(Stations!$A$2:$A$634) -> 633 | C5: Stations sheet, one row per procedure
A6: Training programmes | B6: =COUNTA(Programmes!$A$2:$A$55) -> 54 | C6: Programmes sheet
A7: Stations counted across programmes | B7: =SUM(Programmes!$D$2:$D$55) -> 683 | C7: a station can sit in more than one programme
A8: Mean content eval score | B8: =ROUND(AVERAGE(Stations!$K$2:$K$634),1) -> 95.8 | C8: tools/eval_content.mjs, 0–100
A9: Procedures scoring 95 or more | B9: =COUNTIF(Stations!$K$2:$K$634,">=95") -> 513
A10: Procedures scoring 90 to 94 | B10: =COUNTIFS(Stations!$K$2:$K$634,">=90",Stations!$K$2:$K$634,"<95") -> 115
A11: Procedures under 90 | B11: =COUNTIF(Stations!$K$2:$K$634,"<90") -> 5 | C11: flat sourced briefings and readings
A12: Share at 90 or more | B12: =IFERROR(COUNTIF(Stations!$K$2:$K$634,">=90")/COUNTA(Stations!$A$2:$A$634),0) -> 0.99210111
A13: Total interaction steps | B13: =SUM(Stations!$F$2:$F$634) -> 8473
A14: Total hazards to find | B14: =SUM(Stations!$H$2:$H$634) -> 2550
A15: Unions in the registry | B15: =COUNTA(Unions!$A$2:$A$112) -> 111 | C15: Unions sheet
A16: Checkers passing on every change | B16: =IFERROR(INDEX('Platform Facts'!$B$2:$B$50,MATCH("checkers",'Platform Facts'!$A$2:$A$50,0)),"-") -> 61 | C16: tools/check_all.mjs
A17: Worlds and assets
A18: Open worlds and scenic districts | B18: =COUNTA(Worlds!$A$2:$A$12) -> 11 | C18: Worlds sheet
A19: Job sites across the worlds | B19: =SUM(Worlds!$E$2:$E$12) -> 82
A20: Quests across the worlds | B20: =SUM(Worlds!$I$2:$I$12) -> 153
A21: Easter eggs across the worlds | B21: =SUM(Worlds!$J$2:$J$12) -> 58
A22: Scored activities across the worlds | B22: =SUM(Worlds!$K$2:$K$12) -> 15
A23: 3D builders (equipment, vehicles, boats, props, tools, wildlife) | B23: =COUNTA(Assets!$A$2:$A$132) -> 131 | C23: Assets sheet
A24: Vehicles | B24: =COUNTIF('Vehicles and Boats'!$B$2:$B$33,"vehicle") -> 20 | C24: Vehicles and Boats sheet
A25: Boats and underwater vehicles | B25: =COUNTIF('Vehicles and Boats'!$B$2:$B$33,"boat") -> 12
A26: Builders exported to Unity | B26: =COUNTIF(Assets!$J$2:$J$132,"yes") -> 90 | C26: exports/unity/SmartCitiX/Models/MANIFEST.json
A27: Interfaces
A28: App pages and interfaces | B28: =COUNTA('UI Surfaces'!$A$2:$A$67) -> 66 | C28: UI Surfaces sheet
A30: Largest programmes by station count
A31: Programme | B31: Stations | C31: Eval mean
A32: =INDEX(Programmes!$B$2:$B$55,MATCH(LARGE(Programmes!$M$2:$M$55,1),Programmes!$M$2:$M$55,0)) -> Bay Area Union Edition — Sheet Metal, Bridge, Port and Marine | B32: =INDEX(Programmes!$D$2:$D$55,MATCH(LARGE(Programmes!$M$2:$M$55,1),Programmes!$M$2:$M$55,0)) -> 42 | C32: =INDEX(Programmes!$L$2:$L$55,MATCH(LARGE(Programmes!$M$2:$M$55,1),Programmes!$M$2:$M$55,0)) -> 96.5
A33: =INDEX(Programmes!$B$2:$B$55,MATCH(LARGE(Programmes!$M$2:$M$55,2),Programmes!$M$2:$M$55,0)) -> Pathway Edition — wojrc.org | B33: =INDEX(Programmes!$D$2:$D$55,MATCH(LARGE(Programmes!$M$2:$M$55,2),Programmes!$M$2:$M$55,0)) -> 40 | C33: =INDEX(Programmes!$L$2:$L$55,MATCH(LARGE(Programmes!$M$2:$M$55,2),Programmes!$M$2:$M$55,0)) -> 95.7
A34: =INDEX(Programmes!$B$2:$B$55,MATCH(LARGE(Programmes!$M$2:$M$55,3),Programmes!$M$2:$M$55,0)) -> SF Bay Restoration & Cleanup — Maritime and Underwater | B34: =INDEX(Programmes!$D$2:$D$55,MATCH(LARGE(Programmes!$M$2:$M$55,3),Programmes!$M$2:$M$55,0)) -> 35 | C34: =INDEX(Programmes!$L$2:$L$55,MATCH(LARGE(Programmes!$M$2:$M$55,3),Programmes!$M$2:$M$55,0)) -> 96.3
A35: =INDEX(Programmes!$B$2:$B$55,MATCH(LARGE(Programmes!$M$2:$M$55,4),Programmes!$M$2:$M$55,0)) -> Job Readiness Edition — wojrc.org programmes | B35: =INDEX(Programmes!$D$2:$D$55,MATCH(LARGE(Programmes!$M$2:$M$55,4),Programmes!$M$2:$M$55,0)) -> 32 | C35: =INDEX(Programmes!$L$2:$L$55,MATCH(LARGE(Programmes!$M$2:$M$55,4),Programmes!$M$2:$M$55,0)) -> 95.7
A36: =INDEX(Programmes!$B$2:$B$55,MATCH(LARGE(Programmes!$M$2:$M$55,5),Programmes!$M$2:$M$55,0)) -> Hunters Point Edition — Can We Live? | B36: =INDEX(Programmes!$D$2:$D$55,MATCH(LARGE(Programmes!$M$2:$M$55,5),Programmes!$M$2:$M$55,0)) -> 26 | C36: =INDEX(Programmes!$L$2:$L$55,MATCH(LARGE(Programmes!$M$2:$M$55,5),Programmes!$M$2:$M$55,0)) -> 94
A37: =INDEX(Programmes!$B$2:$B$55,MATCH(LARGE(Programmes!$M$2:$M$55,6),Programmes!$M$2:$M$55,0)) -> Hunters Point Clean-up and Bay Restoration | B37: =INDEX(Programmes!$D$2:$D$55,MATCH(LARGE(Programmes!$M$2:$M$55,6),Programmes!$M$2:$M$55,0)) -> 26 | C37: =INDEX(Programmes!$L$2:$L$55,MATCH(LARGE(Programmes!$M$2:$M$55,6),Programmes!$M$2:$M$55,0)) -> 94.5
A38: =INDEX(Programmes!$B$2:$B$55,MATCH(LARGE(Programmes!$M$2:$M$55,7),Programmes!$M$2:$M$55,0)) -> Situational Awareness — Interruption Drill | B38: =INDEX(Programmes!$D$2:$D$55,MATCH(LARGE(Programmes!$M$2:$M$55,7),Programmes!$M$2:$M$55,0)) -> 22 | C38: =INDEX(Programmes!$L$2:$L$55,MATCH(LARGE(Programmes!$M$2:$M$55,7),Programmes!$M$2:$M$55,0)) -> 94.8
A39: =INDEX(Programmes!$B$2:$B$55,MATCH(LARGE(Programmes!$M$2:$M$55,8),Programmes!$M$2:$M$55,0)) -> Property Management — Twenty Zones | B39: =INDEX(Programmes!$D$2:$D$55,MATCH(LARGE(Programmes!$M$2:$M$55,8),Programmes!$M$2:$M$55,0)) -> 21 | C39: =INDEX(Programmes!$L$2:$L$55,MATCH(LARGE(Programmes!$M$2:$M$55,8),Programmes!$M$2:$M$55,0)) -> 97.6
A40: =INDEX(Programmes!$B$2:$B$55,MATCH(LARGE(Programmes!$M$2:$M$55,9),Programmes!$M$2:$M$55,0)) -> Dental Careers — Unspoken Smiles | B40: =INDEX(Programmes!$D$2:$D$55,MATCH(LARGE(Programmes!$M$2:$M$55,9),Programmes!$M$2:$M$55,0)) -> 19 | C40: =INDEX(Programmes!$L$2:$L$55,MATCH(LARGE(Programmes!$M$2:$M$55,9),Programmes!$M$2:$M$55,0)) -> 96.7
A41: =INDEX(Programmes!$B$2:$B$55,MATCH(LARGE(Programmes!$M$2:$M$55,10),Programmes!$M$2:$M$55,0)) -> Dental Hygiene — Unspoken Smiles | B41: =INDEX(Programmes!$D$2:$D$55,MATCH(LARGE(Programmes!$M$2:$M$55,10),Programmes!$M$2:$M$55,0)) -> 19 | C41: =INDEX(Programmes!$L$2:$L$55,MATCH(LARGE(Programmes!$M$2:$M$55,10),Programmes!$M$2:$M$55,0)) -> 97.1

Sheet Pilot Planner
A1: Pilot planner — a template for a partner cohort
A2: Blue cells on a yellow ground are inputs: change them. Row 5 holds example values only, to show the format; replace them with the pilot's real plan. Black cells are formulas.
A4: Input | B4: Value | C4: Note
A5: Programme id (from the Programmes sheet) | B5: wojrc-pathway-edition | C5: Example value — replace
A6: Learners in the cohort | B6: 12 | C6: Example value — replace
A7: Weeks in the pilot | B7: 8 | C7: Example value — replace
A8: Practice sessions per learner per week | B8: 2 | C8: Example value — replace
A9: Stations attempted per session | B9: 3 | C9: Example value — replace
A11: Derived | B11: Value
A12: Programme name | B12: =IFERROR(INDEX(Programmes!$B$2:$B$55,MATCH($B$5,Programmes!$A$2:$A$55,0)),"id not found") -> Pathway Edition — wojrc.org
A13: Stations in the programme | B13: =IFERROR(INDEX(Programmes!$D$2:$D$55,MATCH($B$5,Programmes!$A$2:$A$55,0)),0) -> 40
A14: Eval mean of its stations | B14: =IFERROR(INDEX(Programmes!$L$2:$L$55,MATCH($B$5,Programmes!$A$2:$A$55,0)),0) -> 95.7
A15: Station attempts across the cohort | B15: =B6*B7*B8*B9 -> 576
A16: Attempts per learner | B16: =B7*B8*B9 -> 48
A17: Times each learner could run every station | B17: =IFERROR(B16/B13,0) -> 1.2

Sheet Programmes
A1: id | B1: name | C1: categoryMix | D1: stationCount | E1: unions | F1: trainingBodies | G1: competencyRequire | H1: ladderLevels | I1: ladderLevelsFull | J1: bayWorldSites | K1: deepSites | L1: evalMean | M1: rankKey
A2: electrical-first-period | B2: Inside Wireman — First Period | C2: Energy & Power: 7; Trade Skills Simulator: 1 | D2: 8 | E2: ibew | F2: ibew-neca-jatc | G2: 4 | H2: 20 | I2: 19 | J2: west-oakland-substation-yard | L2: 96.6 | M2: =D2+ROW()/100000 -> 8.00002
A3: confined-space | B3: Confined Space — Entry and Rescue | C3: Water & Environmental: 7; Emergency Services: 1 | D3: 8 | E3: iaff; iuoe; liuna; ua | F3: iaff-training; iuoe-training; liuna-training-fund; ua-apprenticeship | G3: 4 | H3: 20 | I3: 20 | J3: south-treatment-plant; west-oakland-utility-yard | K3: outfall-intake-lockout-site | L3: 96.3 | M3: =D3+ROW()/100000 -> 8.00003
A4: fall-protection | B4: Working at Height — Fall Protection | C4: Construction & Structural Trades: 4; Connectivity & Telecom: 2; Emergency Services: 1 | D4: 7 | E4: carpenters; cwa; ironworkers | F4: carpenters-ictf; cwa-training; ironworkers-impact | G4: 4 | H4: 20 | I4: 20 | J4: downtown-tower-site | L4: 95.6 | M4: =D4+ROW()/100000 -> 7.00004
A5: hazmat-environmental | B5: Hazmat and Environmental Response | C5: Environmental Monitoring: 6; Emergency Services: 2; Surface Prep & Coatings: 1; Water & Environmental: 1 | D5: 10 | E5: iaff; liuna | F5: iaff-training; liuna-training-fund | G5: 5 | H5: 20 | I5: 20 | J5: port-hazmat-response-yard | K5: outfall-diffuser-inspection | L5: 92.5 | M5: =D5+ROW()/100000 -> 10.00005
A6: rigging-lifting | B6: Rigging and Lifting | C6: Entertainment & Live Events: 3; Construction & Structural Trades: 2; Maritime & Ports: 1 | D6: 6 | E6: iatse; ilwu; ironworkers; iuoe | F6: iatse-training-trust; ilwu-pma-training; ironworkers-impact; iuoe-training | G6: 3 | H6: 20 | I6: 20 | J6: port-container-terminal | K6: shelf-lift-bag-site; wreck-salvage-rigging | L6: 93.8 | M6: =D6+ROW()/100000 -> 6.00006
A7: stationary-engineer | B7: Stationary Engineer — Building Plant | C7: Building Systems & Facilities: 7 | D7: 7 | E7: iuoe | F7: iuoe-training; ua-apprenticeship | G7: 4 | H7: 20 | I7: 20 | J7: downtown-central-plant; south-treatment-plant | L7: 93.3 | M7: =D7+ROW()/100000 -> 7.00007
A8: port-operations | B8: Port and Terminal Operations | C8: Maritime & Ports: 7 | D8: 7 | E8: ilwu; meba; siu; teamsters | F8: ilwu-pma-training; meba-calhoon-school; siu-paul-hall-center; teamsters-training | G8: 4 | H8: 20 | I8: 20 | J8: channel-buoy-tender-pier; island-yacht-harbor; port-container-terminal; south-shoreline-marina | K8: approach-buoy-tender-station; reef-ball-placement-site | L8: 94.3 | M8: =D8+ROW()/100000 -> 7.00008
A9: transit-ramp | B9: Transit and Ramp Operations | C9: Mobility & Transit: 6; Manufacturing & Automation: 1 | D9: 7 | E9: atu; iam; ibew; twu | F9: atu-training; bmwed-training; iam-winpisinger-center; ibew-neca-jatc; twu-training | G9: 4 | H9: 20 | I9: 20 | J9: coliseum-elevated-transit-station; island-ferry-landing | L9: 94.7 | M9: =D9+ROW()/100000 -> 7.00009
A10: energy-transition | B10: Energy Transition Systems | C10: Energy & Power: 8; Connectivity & Telecom: 1 | D10: 9 | E10: ibew | F10: ibew-neca-jatc | G10: 5 | H10: 20 | I10: 20 | J10: hills-transmission-corridor; ridge-reservoir-yard | L10: 97.1 | M10: =D10+ROW()/100000 -> 9.0001
A11: live-events | B11: Live Events Production | C11: Entertainment & Live Events: 7 | D11: 7 | E11: iatse | F11: iatse-training-trust | G11: 4 | H11: 20 | I11: 20 | J11: coliseum-stadium | L11: 95.3 | M11: =D11+ROW()/100000 -> 7.00011
A12: hunters-point-bay-restoration | B12: Hunters Point Clean-up and Bay Restoration | C12: Environmental Monitoring: 11; Water & Environmental: 9; Maritime & Ports: 3; Building Systems & Facilities: 1; Emergency Services: 1; Energy & Power: 1 | D12: 26 | E12: carpenters; ibu; iuoe; iuoe-local3; liuna; teamsters; ua | F12: carpenters-ictf; ilwu-pma-training; iuoe-local3-training; iuoe-training; liuna-training-fund; teamsters-training; ua-apprenticeship | G12: 6 | H12: 20 | I12: 20 | J12: estuary-shoreline-park-trailhead; north-shoreline-field-lab | K12: channel-dredge-survey; eelgrass-transplant-plots; marsh-mouth-invasive-plot; marsh-mouth-tide-gate; mud-plain-hotspot-survey; pier-creosote-pile-site; reef-ball-monitoring-plot | L12: 94.5 | M12: =D12+ROW()/100000 -> 26.00012
A13: culinary-kitchen | B13: Culinary — The Working Kitchen | C13: Culinary & Hospitality: 15; Trade Skills Simulator: 1 | D13: 16 | E13: afscme; seiu; unite-here | F13: afscme-training; seiu-training; unite-here-training | G13: 6 | H13: 20 | I13: 20 | J13: uptown-restaurant-row | L13: 94.1 | M13: =D13+ROW()/100000 -> 16.00013
A14: dental-hygiene-unspoken-smiles | B14: Dental Hygiene — Unspoken Smiles | C14: Dental & Oral Health: 18; Trade Skills Simulator: 1 | D14: 19 | E14: afscme; seiu; ufcw | F14: afscme-training; seiu-training; ufcw-training | G14: 6 | H14: 20 | I14: 20 | J14: fruitvale-community-college | L14: 97.1 | M14: =D14+ROW()/100000 -> 19.00014
A15: dental-careers-unspoken-smiles | B15: Dental Careers — Unspoken Smiles | C15: Dental & Oral Health: 19 | D15: 19 | E15: afscme; seiu; ufcw | F15: afscme-training; seiu-training; ufcw-training | G15: 6 | H15: 20 | I15: 20 | J15: fruitvale-community-college | L15: 96.7 | M15: =D15+ROW()/100000 -> 19.00015
A16: civic-leadership-and-ei | B16: Civic Leadership and Emotional Intelligence | C16: Community Environmental Justice: 17 | D16: 17 | E16: afscme; seiu | F16: afscme-training; seiu-training | G16: 6 | H16: 20 | I16: 20 | J16: downtown-civic-center | L16: 96.4 | M16: =D16+ROW()/100000 -> 17.00016
A17: property-management | B17: Property Management — Twenty Zones | C17: Building Systems & Facilities: 21 | D17: 21 | E17: iuoe; seiu; seiu-uswtw; unite-here | F17: iuoe-training; seiu-training; seiu-uswtw-training; unite-here-training | G17: 6 | H17: 20 | I17: 20 | J17: downtown-housing-block | L17: 97.6 | M17: =D17+ROW()/100000 -> 21.00017
A18: outbreak-response-who | B18: Outbreak and Disease Response — WHO and UN Practice | C18: Emergency Services: 11 | D18: 11 | E18: afscme; cna; nnu; seiu | F18: afscme-training; seiu-training | G18: 6 | H18: 20 | I18: 20 | J18: coliseum-area-hospital; emery-lab-campus | L18: 97.6 | M18: =D18+ROW()/100000 -> 11.00018
A19: job-readiness-edition | B19: Job Readiness Edition — wojrc.org programmes | C19: Mobility & Transit: 16; Community Environmental Justice: 15; Manufacturing & Automation: 1 | D19: 32 | E19: afscme; ilwu; seiu; teamsters | F19: afscme-training; ilwu-pma-training; seiu-training; teamsters-training | G19: 6 | H19: 20 | I19: 20 | J19: emery-distribution-center; west-oakland-truck-yard | L19: 95.7 | M19: =D19+ROW()/100000 -> 32.00019
A20: bay-area-union-edition | B20: Bay Area Union Edition — Sheet Metal, Bridge, Port and Marine | C20: Maritime & Ports: 24; Construction & Structural Trades: 9; Manufacturing & Automation: 9 | D20: 42 | E20: carpenters; ibu; ilwu; ironworkers; iuoe; iupat; meba; siu; smart | F20: carpenters-ictf; ilwu-pma-training; ironworkers-impact; iuoe-training; iupat-fti; meba-calhoon-school; siu-paul-hall-center; smart-iti | G20: 6 | H20: 20 | I20: 20 | J20: island-boatyard; island-ferry-landing; island-yacht-harbor; west-oakland-union-hall | K20: approach-boom-tow-site; channel-scour-survey; flats-workboat-anchorage; kelp-night-line-site; outfall-intake-lockout-site; pier-piling-inspection-station; shelf-lift-bag-site; trench-rov-station; wreck-photo-survey | L20: 96.5 | M20: =D20+ROW()/100000 -> 42.0002
A21: bartending-course | B21: Bartending — Behind the Bar | C21: Culinary & Hospitality: 15; Trade Skills Simulator: 1 | D21: 16 | E21: unite-here | F21: unite-here-training | G21: 6 | H21: 20 | I21: 20 | J21: uptown-theatre-district | L21: 94.6 | M21: =D21+ROW()/100000 -> 16.00021
A22: hunters-point-can-we-live | B22: Hunters Point Edition — Can We Live? | C22: Community Environmental Justice: 26 | D22: 26 | E22: iuoe; liuna; teamsters | F22: iuoe-training; liuna-training-fund; seiu-training; teamsters-training | G22: 6 | H22: 20 | I22: 20 | J22: estuary-shoreline-park-trailhead | K22: flats-sediment-core-site; outfall-discharge-photo-point | L22: 94 | M22: =D22+ROW()/100000 -> 26.00022
A23: sewing-garment-trades | B23: Sewing and Garment Trades | C23: Sewing & Garment Trades: 10; Trade Skills Simulator: 1 | D23: 11 | E23: seiu; unite-here; workers-united | F23: seiu-training; unite-here-training | G23: 6 | H23: 20 | I23: 20 | J23: west-oakland-warehouse-district | L23: 96.2 | M23: =D23+ROW()/100000 -> 11.00023
A24: bridge-and-structural | B24: Bridge and Structural Trades | C24: Construction & Structural Trades: 7 | D24: 7 | E24: ironworkers; iuoe; iupat; liuna | F24: ironworkers-impact; iuoe-training; iupat-fti; liuna-training-fund | G24: 4 | H24: 20 | I24: 20 | J24: bridge-approach-toll-plaza | K24: channel-scour-survey | L24: 95.6 | M24: =D24+ROW()/100000 -> 7.00024
A25: hotel-workers | B25: Hotel Workers — Back of House | C25: Culinary & Hospitality: 7 | D25: 7 | E25: unite-here | F25: unite-here-training | G25: 4 | H25: 20 | I25: 20 | J25: uptown-hotel-row | L25: 96.9 | M25: =D25+ROW()/100000 -> 7.00025
A26: builders-trades | B26: Builders — Carpenters, Laborers and Masons | C26: Construction & Structural Trades: 8 | D26: 8 | E26: bac; carpenters; iuoe; liuna | F26: bac-imi; carpenters-ictf; iuoe-training; liuna-training-fund | G26: 4 | H26: 20 | I26: 20 | J26: uptown-construction-site | L26: 96.1 | M26: =D26+ROW()/100000 -> 8.00026
A27: first-responders | B27: First Responders — Fire, EMS, Police, Crisis and Relief | C27: Emergency Services: 17 | D27: 17 | E27: afscme; fop; iaff; liuna; nage; nasw; seiu; seiu-1021 | F27: afscme-training; iaff-training; liuna-training-fund; naemt-courses; nasw-code-of-ethics; seiu-1021-training; seiu-training | G27: 6 | H27: 20 | I27: 20 | J27: fruitvale-fire-station; ridge-fire-lookout | K27: seamount-capstone-survey | L27: 95.8 | M27: =D27+ROW()/100000 -> 17.00027
A28: situational-awareness | B28: Situational Awareness — Interruption Drill | C28: Building Systems & Facilities: 3; Construction & Structural Trades: 3; Energy & Power: 3; Trade Skills Simulator: 3; Connectivity & Telecom: 2; Emergency Services: 2; Manufacturing & Automation: 2; Water & Environmental: 2; Maritime & Ports: 1; Mobility & Transit: 1 | D28: 22 | E28: iaff; ibew; ironworkers; liuna; ua | F28: iaff-training; ibew-neca-jatc; ironworkers-impact; liuna-training-fund; ua-apprenticeship | G28: 6 | H28: 20 | I28: 20 | J28: lake-loop-boathouse | K28: shelf-checkout-site | L28: 94.8 | M28: =D28+ROW()/100000 -> 22.00028
A29: ports-maritime-ecology | B29: Ports, Maritime and Bay Ecology | C29: Maritime & Ports: 11 | D29: 11 | E29: ibew; ibu; ilwu; liuna | F29: afscme-training; ibew-neca-jatc; ilwu-pma-training; liuna-training-fund | G29: 6 | H29: 20 | I29: 20 | J29: channel-buoy-tender-pier; estuary-research-dock; north-marina-pier | K29: approach-buoy-tender-station; reef-ball-monitoring-plot | L29: 94.3 | M29: =D29+ROW()/100000 -> 11.00029
A30: air-quality-monitoring | B30: Air Quality — Monitoring and Control | C30: Environmental Monitoring: 6 | D30: 6 | E30: afscme; iuoe; liuna; usw | F30: afscme-training; iuoe-training; liuna-training-fund; usw-mazzocchi-center | G30: 3 | H30: 20 | I30: 20 | J30: north-shoreline-field-lab; west-oakland-air-monitoring-post | K30: flats-sonde-station | L30: 94.2 | M30: =D30+ROW()/100000 -> 6.0003
A31: basketball-fundamentals | B31: Basketball Fundamentals | C31: Youth Sports & Coaching: 18 | D31: 18 | E31: afscme; seiu | F31: afscme-training; seiu-training | G31: 6 | H31: 20 | I31: 20 | J31: coliseum-arena | L31: 96.5 | M31: =D31+ROW()/100000 -> 18.00031
A32: bay-restoration-maritime-underwater | B32: SF Bay Restoration & Cleanup — Maritime and Underwater | C32: Maritime & Ports: 16; Environmental Monitoring: 10; Water & Environmental: 9 | D32: 35 | E32: afscme; carpenters; ibu; ilwu; iuoe; iuoe-local3; liuna; meba; seiu; siu | F32: afscme-training; carpenters-ictf; ilwu-pma-training; iuoe-local3-training; iuoe-training; liuna-training-fund; meba-calhoon-school; seiu-training; siu-paul-hall-center | G32: 6 | H32: 20 | I32: 20 | J32: estuary-marina-boatyard; island-boatyard; north-marina-pier; north-shoreline-field-lab; south-shoreline-marina | K32: approach-boom-tow-site; channel-dredge-survey; eelgrass-fish-census-line; eelgrass-turbidity-curtain; flats-sediment-core-site; flats-sonde-station; flats-workboat-anchorage; kelp-transect-start; marsh-mouth-culvert; marsh-mouth-invasive-plot; mud-plain-hotspot-survey; mud-plain-trash-capture; pier-surface-supplied-station; reef-ball-placement-site; seamount-capstone-survey; shelf-checkout-site; shelf-debris-sweep; wreck-photo-survey; wreck-salvage-rigging | L32: 96.3 | M32: =D32+ROW()/100000 -> 35.00032
A33: railroad-crafts | B33: Railroad Crafts — Track, Car and Cab | C33: Mobility & Transit: 8 | D33: 8 | E33: blet; bmwed; smart; smart-td | F33: blet-training; bmwed-training; smart-iti; smarttd-training | G33: 4 | H33: 20 | I33: 20 | J33: port-rail-yard | L33: 95.3 | M33: =D33+ROW()/100000 -> 8.00033
A34: heavy-equipment-operators | B34: Heavy Equipment Operators — IUOE Local 3 | C34: Construction & Structural Trades: 8 | D34: 8 | E34: iuoe | F34: iuoe-training | G34: 4 | H34: 20 | I34: 20 | J34: hills-grading-site; ridge-reservoir-yard | K34: pier-creosote-pile-site | L34: 94.9 | M34: =D34+ROW()/100000 -> 8.00034
A35: plumbers-and-pipefitters | B35: Plumbers and Pipefitters — Journeyman Rough-In and Test Block | C35: Building Systems & Facilities: 7; Water & Environmental: 1 | D35: 8 | E35: ua | F35: ua-apprenticeship | G35: 4 | H35: 20 | I35: 20 | J35: port-maintenance-shop | L35: 96.5 | M35: =D35+ROW()/100000 -> 8.00035
A36: glaziers-and-architectural-metal | B36: Glaziers and Architectural Metal | C36: Construction & Structural Trades: 8 | D36: 8 | E36: iupat; iupat-dc16 | F36: iupat-dc16-glaziers; iupat-fti | G36: 4 | H36: 20 | I36: 20 | J36: downtown-tower-site | L36: 95.6 | M36: =D36+ROW()/100000 -> 8.00036
A37: elevator-constructors | B37: Elevator Constructor — IUEC Core Skills | C37: Building Systems & Facilities: 8 | D37: 8 | E37: iuec | F37: neiep-training | G37: 4 | H37: 20 | I37: 20 | J37: downtown-tower-site | L37: 95.1 | M37: =D37+ROW()/100000 -> 8.00037
A38: insulators-and-boilermakers | B38: Insulators and Boilermakers — Building Systems | C38: Building Systems & Facilities: 8 | D38: 8 | E38: ibb; insulators | F38: boilermakers-local-549; insulators-local-16 | G38: 4 | H38: 20 | I38: 20 | J38: port-maintenance-shop | L38: 96.6 | M38: =D38+ROW()/100000 -> 8.00038
A39: cement-masons-and-plasterers | B39: Cement Masons and Plasterers | C39: Construction & Structural Trades: 8 | D39: 8 | E39: opcmia | F39: opcmia-local-300 | G39: 4 | H39: 20 | I39: 20 | J39: uptown-construction-site | L39: 96.1 | M39: =D39+ROW()/100000 -> 8.00039
A40: healthcare-support | B40: Healthcare Support | C40: Healthcare Support: 8 | D40: 8 | E40: nuhw; seiu; seiu-uhw | F40: nuhw-training; seiu-training; seiu-uhw-training | G40: 4 | H40: 20 | I40: 20 | J40: coliseum-area-hospital; emery-lab-campus | L40: 96 | M40: =D40+ROW()/100000 -> 8.0004
...

Sheet Stations
A1: id | B1: app | C1: title | D1: category | E1: programmes | F1: steps | G1: kinds | H1: hazards | I1: interruptions | J1: citations | K1: evalScore | L1: standardsScore | M1: meshes
A2: abatement-chamber | B2: smartcity | C2: SmartCiti.X~ Abatement Chamber VR | D2: Water & Environmental | E2: hazmat-environmental | F2: 12 | G2: select; find; gauge; sequence; hold; track; drag | H2: 5 | I2: 0 | J2: 4 | K2: 90 | L2: 75 | M2: 113
A3: abatement-perimeter-awareness | B3: smartcity | C3: SmartCiti.X~ Abatement Perimeter Awareness VR | D3: Community Environmental Justice | E3: hunters-point-can-we-live | F3: 14 | G3: select; sequence; find; track; hold; gauge; turn; drag | H3: 4 | I3: 2 | J3: 4 | K3: 97 | L3: 100 | M3: 183
A4: aerial-ladder | B4: smartcity | C4: SmartCiti.X~ Aerial Ladder VR | D4: Emergency Services | E4: fall-protection | F4: 12 | G4: select; sequence; drag; gauge; turn; track; find | H4: 4 | I4: 2 | J4: 5 | K4: 94 | L4: 100 | M4: 167
A5: aerial-lashing | B5: smartcity | C5: SmartCiti.X~ Aerial Lashing VR | D5: Connectivity & Telecom | F5: 14 | G5: select; drag; hold; sequence; gauge; track; turn; find | H5: 4 | I5: 2 | J5: 7 | K5: 95 | L5: 100 | M5: 261
A6: aerosol-management | B6: smartcity | C6: SmartCiti.X~ Aerosol Management VR | D6: Dental & Oral Health | E6: dental-hygiene-unspoken-smiles | F6: 15 | G6: select; find; gauge; sequence; hold; drag; track | H6: 4 | I6: 2 | J6: 6 | K6: 96 | L6: 100 | M6: 164
A7: air-monitor | B7: smartcity | C7: SmartCiti.X~ Perimeter Air VR | D7: Environmental Monitoring | E7: air-quality-monitoring; hazmat-environmental; hunters-point-bay-restoration | F7: 10 | G7: select; sequence; gauge; hold; turn; find | H7: 4 | I7: 2 | J7: 3 | K7: 92 | L7: 67 | M7: 208
A8: air-network-data-qa | B8: smartcity | C8: SmartCiti.X~ Network Data Review VR | D8: Community Environmental Justice | E8: hunters-point-can-we-live | F8: 13 | G8: select; sequence; find; hold; gauge; track | H8: 4 | I8: 2 | J8: 3 | K8: 97 | L8: 100 | M8: 159
A9: air-sensor-install | B9: smartcity | C9: SmartCiti.X~ Neighbourhood Air Sensor VR | D9: Community Environmental Justice | E9: hunters-point-can-we-live | F9: 14 | G9: select; sequence; turn; find; hold; gauge; track | H9: 4 | I9: 2 | J9: 4 | K9: 93 | L9: 75 | M9: 213
A10: airport-ramp | B10: smartcity | C10: SmartCiti.X~ Airport Ramp VR | D10: Mobility & Transit | E10: situational-awareness; transit-ramp | F10: 11 | G10: select; find; sequence; track; gauge; drag | H10: 4 | I10: 2 | J10: 4 | K10: 96 | L10: 100 | M10: 180
A11: allergen-cocktail | B11: smartcity | C11: SmartCiti.X~ Allergens & Honest Drinks VR | D11: Culinary & Hospitality | E11: bartending-course | F11: 15 | G11: select; find; sequence; drag; hold; track | H11: 4 | I11: 2 | J11: 6 | K11: 93 | L11: 83 | M11: 166
A12: allergen-control | B12: smartcity | C12: SmartCiti.X~ Allergen Control VR | D12: Culinary & Hospitality | E12: culinary-kitchen | F12: 12 | G12: select; sequence; hold; find; drag; track | H12: 4 | I12: 2 | J12: 8 | K12: 93 | L12: 75 | M12: 150
A13: alteration-repair-ticket | B13: smartcity | C13: SmartCiti.X~ Alteration Repair Ticket VR | D13: Sewing & Garment Trades | E13: sewing-garment-trades | F13: 13 | G13: select; drag; gauge; sequence; track; hold; find | H13: 4 | I13: 2 | J13: 4 | K13: 97 | L13: 100 | M13: 152
A14: amalgam-waste-handling | B14: smartcity | C14: SmartCiti.X~ Amalgam Waste Handling VR | D14: Dental & Oral Health | E14: dental-hygiene-unspoken-smiles | F14: 15 | G14: turn; track; select; gauge; sequence; drag; find; hold | H14: 4 | I14: 2 | J14: 4 | K14: 96 | L14: 100 | M14: 163
A15: ambulance-scene-safety | B15: smartcity | C15: SmartCiti.X~ Ambulance Scene Safety VR | D15: Emergency Services | E15: first-responders | F15: 15 | G15: select; turn; sequence; drag; track; hold; find; gauge | H15: 4 | I15: 2 | J15: 6 | K15: 96 | L15: 100 | M15: 217
A16: ammonia-plant | B16: smartcity | C16: SmartCiti.X~ Ammonia Plant VR | D16: Building Systems & Facilities | F16: 16 | G16: select; turn; drag; gauge; sequence; find; track | H16: 4 | I16: 2 | J16: 9 | K16: 96 | L16: 100 | M16: 221
A17: apprenticeship-application-and-test | B17: smartcity | C17: SmartCiti.X~ Apprenticeship Application & Test VR | D17: Community Environmental Justice | E17: job-readiness-edition; wojrc-pathway-edition | F17: 12 | G17: select; find; sequence; hold; drag; turn; gauge; track | H17: 4 | I17: 2 | J17: 6 | K17: 98 | L17: 100 | M17: 188
A18: apprenticeship-standards-reading | B18: smartcity | C18: SmartCiti.X~ Reading an Apprenticeship Standard VR | D18: Community Environmental Justice | E18: job-readiness-edition; wojrc-pathway-edition | F18: 10 | G18: select; find; sequence | H18: 4 | I18: 0 | J18: 5 | K18: 88 | L18: 100 | M18: 0
A19: arc-flash-label-study | B19: smartcity | C19: SmartCiti.X~ Arc-Flash Label Study VR | D19: Energy & Power | E19: electrical-first-period | F19: 13 | G19: select; sequence; gauge; drag; find | H19: 4 | I19: 2 | J19: 5 | K19: 95 | L19: 100 | M19: 152
A20: arena-rigging | B20: smartcity | C20: SmartCiti.X~ Arena Rigging VR | D20: Entertainment & Live Events | F20: 14 | G20: select; sequence; gauge; drag; turn; track; hold; find | H20: 5 | I20: 2 | J20: 3 | K20: 96 | L20: 100 | M20: 270
A21: av-baggage-belt-loader-and-hold-loading | B21: smartcity | C21: SmartCiti.X~ Baggage Belt-Loader & Hold Loading VR | D21: Mobility & Transit | E21: aviation-maintenance-and-ground | F21: 15 | G21: sequence; select; find; drag; turn; track; gauge; hold | H21: 4 | I21: 2 | J21: 5 | K21: 96 | L21: 100 | M21: 168
A22: av-borescope-and-tool-control-inventory | B22: smartcity | C22: SmartCiti.X~ Borescope & Tool-Control Inventory VR | D22: Mobility & Transit | E22: aviation-maintenance-and-ground | F22: 15 | G22: sequence; select; gauge; drag; track; find; hold | H22: 4 | I22: 2 | J22: 6 | K22: 96 | L22: 100 | M22: 158
A23: av-deicing-truck-boom-operations | B23: smartcity | C23: SmartCiti.X~ De-icing Truck Boom Operations VR | D23: Mobility & Transit | E23: aviation-maintenance-and-ground | F23: 14 | G23: sequence; select; find; drag; turn; gauge; hold | H23: 4 | I23: 2 | J23: 7 | K23: 96 | L23: 100 | M23: 160
A24: av-ground-power-and-static-bonding-before-fuel | B24: smartcity | C24: SmartCiti.X~ Ground Power & Static Bonding Before Fuel VR | D24: Mobility & Transit | E24: aviation-maintenance-and-ground | F24: 14 | G24: sequence; select; find; drag; hold; track; gauge | H24: 4 | I24: 2 | J24: 7 | K24: 95 | L24: 100 | M24: 200
A25: av-hangar-jacking-and-stands | B25: smartcity | C25: SmartCiti.X~ Hangar Jacking & Stands VR | D25: Mobility & Transit | E25: aviation-maintenance-and-ground | F25: 15 | G25: sequence; select; find; track; turn; gauge; drag; hold | H25: 4 | I25: 2 | J25: 6 | K25: 95 | L25: 100 | M25: 183
A26: av-lavatory-and-potable-water-separation | B26: smartcity | C26: SmartCiti.X~ Lavatory & Potable Water Separation VR | D26: Mobility & Transit | E26: aviation-maintenance-and-ground | F26: 15 | G26: sequence; select; find; drag; turn; hold; track; gauge | H26: 4 | I26: 2 | J26: 5 | K26: 95 | L26: 100 | M26: 156
A27: av-marshalling-and-wingwalker-signals | B27: smartcity | C27: SmartCiti.X~ Marshalling & Wing-Walker Signals VR | D27: Mobility & Transit | E27: aviation-maintenance-and-ground | F27: 14 | G27: sequence; select; find; drag; track; hold; gauge | H27: 4 | I27: 2 | J27: 7 | K27: 95 | L27: 100 | M27: 191
A28: av-pushback-tug-and-towbar-connection | B28: smartcity | C28: SmartCiti.X~ Pushback Tug & Towbar Connection VR | D28: Mobility & Transit | E28: aviation-maintenance-and-ground | F28: 15 | G28: sequence; select; find; drag; hold; track; turn; gauge | H28: 4 | I28: 2 | J28: 6 | K28: 95 | L28: 100 | M28: 163
A29: backflow-test | B29: smartcity | C29: SmartCiti.X~ Backflow Test VR | D29: Water & Environmental | F29: 11 | G29: select; sequence; find; hold; turn; gauge; track | H29: 4 | I29: 2 | J29: 6 | K29: 95 | L29: 83 | M29: 164
A30: bakery-mixer | B30: smartcity | C30: SmartCiti.X~ Bakery Mixer VR | D30: Culinary & Hospitality | E30: culinary-kitchen | F30: 14 | G30: select; hold; turn; drag; gauge; track; find | H30: 4 | I30: 2 | J30: 7 | K30: 93 | L30: 86 | M30: 152
A31: ballast-water-sampling | B31: smartcity | C31: SmartCiti.X~ Ballast Water Sampling VR | D31: Maritime & Ports | E31: ports-maritime-ecology | F31: 13 | G31: select; turn; track; drag; hold; sequence; gauge; find | H31: 4 | I31: 2 | J31: 6 | K31: 97 | L31: 100 | M31: 214
A32: banquet-hot-hold | B32: smartcity | C32: SmartCiti.X~ Banquet Hot Hold VR | D32: Culinary & Hospitality | E32: culinary-kitchen; hotel-workers | F32: 14 | G32: select; turn; gauge; drag; sequence; track; find; hold | H32: 4 | I32: 2 | J32: 7 | K32: 95 | L32: 86 | M32: 212
A33: banquet-setup-lift | B33: smartcity | C33: SmartCiti.X~ Banquet Setup Lift VR | D33: Culinary & Hospitality | E33: hotel-workers | F33: 14 | G33: select; drag; hold; sequence; gauge; turn; find | H33: 4 | I33: 2 | J33: 4 | K33: 97 | L33: 100 | M33: 182
A34: bar-well-setup | B34: smartcity | C34: SmartCiti.X~ Opening the Well VR | D34: Culinary & Hospitality | E34: bartending-course | F34: 12 | G34: select; gauge; sequence; hold; drag; track; find | H34: 4 | I34: 2 | J34: 8 | K34: 95 | L34: 88 | M34: 162
A35: battery-storage-container-commissioning | B35: smartcity | C35: SmartCiti.X~ Battery Storage Container Commissioning VR | D35: Energy & Power | E35: energy-transition | F35: 15 | G35: select; find; gauge; sequence; drag; hold; turn; track | H35: 4 | I35: 2 | J35: 8 | K35: 97 | L35: 100 | M35: 229
A36: battery-yard | B36: smartcity | C36: SmartCiti.X~ Battery Yard VR | D36: Energy & Power | E36: electrical-first-period; energy-transition | F36: 12 | G36: select; sequence; hold; gauge; drag; find | H36: 4 | I36: 2 | J36: 5 | K36: 98 | L36: 100 | M36: 209
A37: bb-coach-feedback-and-growth-mindset | B37: smartcity | C37: SmartCiti.X~ Coach Feedback and Growth Mindset VR | D37: Youth Sports & Coaching | E37: basketball-fundamentals | F37: 14 | G37: find; select; hold; sequence; turn; gauge; drag; track | H37: 4 | I37: 2 | J37: 6 | K37: 96 | L37: 100 | M37: 201
A38: bb-composure-with-a-hostile-crowd-and-officials | B38: smartcity | C38: SmartCiti.X~ Composure with a Hostile Crowd and Officials VR | D38: Youth Sports & Coaching | E38: basketball-fundamentals | F38: 14 | G38: find; select; hold; sequence; turn; gauge; drag; track | H38: 4 | I38: 2 | J38: 6 | K38: 96 | L38: 100 | M38: 252
A39: bb-defensive-stance-and-closeouts | B39: smartcity | C39: SmartCiti.X~ Defensive Stance and Closeouts VR | D39: Youth Sports & Coaching | E39: basketball-fundamentals | F39: 14 | G39: find; select; sequence; hold; track; gauge; turn; drag | H39: 4 | I39: 2 | J39: 5 | K39: 97 | L39: 100 | M39: 223
A40: bb-dribble-moves-and-change-of-pace | B40: smartcity | C40: SmartCiti.X~ Dribble Moves and Change of Pace VR | D40: Youth Sports & Coaching | E40: basketball-fundamentals | F40: 14 | G40: find; select; sequence; gauge; turn; hold; track; drag | H40: 4 | I40: 2 | J40: 5 | K40: 95 | L40: 100 | M40: 170
...

Sheet Assets
A1: name | B1: family | C1: build | D1: meshes | E1: footprint | F1: parts | G1: note | H1: stationCount | I1: stations | J1: unity | K1: source
A2: excavator | B2: equipment | C2: excavator | D2: 21 | E2: 3.05 x 4.83 x 10.78 | F2: trackL; trackR; house; door; boom; stick; bucket; lights; counterweight | G2: 20 t tracked excavator, dig-ready | H2: 8 | I2: br-barge-loading-of-contaminated-sediment; br-culvert-retrofit-for-fish-passage; br-dredge-material-screening-and-disposal-decision; br-dredge-spoils-dewatering-pad; br-legacy-mercury-and-pcb-hotspot-handling; br-turbidity-curtain-deployment; br-water-quality-sonde-calibration-and-deploy; op-excavator-trench-and-utility-locate | J2: yes | K2: WebXR/shared/equipment.js EQUIPMENT_BUDGET
A3: amphibiousExcavator | B3: equipment | C3: amphibiousExcavator | D3: 22 | E3: 4.65 x 5.21 x 10.81 | F3: pontoonL; pontoonR; house; door; boom; stick; bucket; lights; counterweight | G3: amphibious pontoon excavator, dig-ready | H3: 2 | I3: br-bird-nesting-buffer-and-work-window; br-tidal-marsh-grading-amphibious-excavator | J3: yes | K3: WebXR/shared/equipment.js EQUIPMENT_BUDGET
A4: backhoe | B4: equipment | C4: backhoe | D4: 23 | E4: 2.36 x 3.75 x 7.46 | F4: loaderArms; loaderBucket; swingFrame; boom; stick; bucket; stabilizers; wheels; door; lights | G4: loader backhoe, travel pose | H4: 1 | I4: op-equipment-daily-walkaround-and-fluids | J4: yes | K4: WebXR/shared/equipment.js EQUIPMENT_BUDGET
A5: skidSteer | B5: equipment | C5: skidSteer | D5: 12 | E5: 1.83 x 2.07 x 3.31 | F5: arms; bucket; wheelsL; wheelsR; wheels; door; lights | G5: wheeled skid steer | H5: 2 | I5: bt-rebar-tying-and-impalement-protection; ut-service-line-locate-and-hand-dig-near-gas-main | J5: yes | K5: WebXR/shared/equipment.js EQUIPMENT_BUDGET
A6: dumpTruck | B6: equipment | C6: dumpTruck | D6: 20 | E6: 3.02 x 3.26 x 9.57 | F6: bed; tailgate; hoist; doorL; doorR; mirrorL; mirrorR; wheels; lights | G6: tri-axle dump truck | H6: 3 | I6: br-legacy-mercury-and-pcb-hotspot-handling; mm-haul-truck-berm; op-loader-truck-loading-and-blind-spots | J6: yes | K6: WebXR/shared/equipment.js EQUIPMENT_BUDGET
A7: mobileCrane | B7: equipment | C7: mobileCrane | D7: 27 | E7: 2.96 x 3.49 x 11.46 | F7: outriggers; house; counterweight; cabDoor; boom; boomSections; hook; wheels; lights | G7: rough-terrain crane, travel pose | H7: 4 | I7: br-trash-capture-device-service; bs-tandem-lift-girder-set; gl-glass-handling-cart-and-crane-vacuum-lifter; rl-critical-lift-plan-and-signalperson | J7: yes | K7: WebXR/shared/equipment.js EQUIPMENT_BUDGET
A8: aerialBoomLift | B8: equipment | C8: aerialBoomLift | D8: 19 | E8: 2.42 x 2.61 x 9 | F8: turntable; boom; boomTele; jib; platform; controls; groundControls; wheels; beacon | G8: 60 ft telescopic boom lift, stowed | H8: 2 | I8: bs-tandem-lift-girder-set; fp-anchor-selection-and-rescue-plan | J8: yes | K8: WebXR/shared/equipment.js EQUIPMENT_BUDGET
A9: scissorLift | B9: equipment | C9: scissorLift | D9: 15 | E9: 1.16 x 2.34 x 2.3 | F9: scissors; platform; extensionDeck; controls; gate; potholeGuards; wheels; beacon | G9: 26 ft slab scissor, stowed | H9: 2 | I9: le-followspot-and-truss-access-at-height; tw-high-bay-order-picker-fall-protection | J9: yes | K9: WebXR/shared/equipment.js EQUIPMENT_BUDGET
A10: compactor | B10: equipment | C10: compactor | D10: 14 | E10: 2.4 x 3.12 x 5.68 | F10: frontFrame; drum; wheels; rops; seat; controls; lights; beacon | G10: single-drum soil compactor | H10: 2 | I10: cm-curb-and-gutter-forms-and-finish; op-compactor-lift-thickness-and-edge | J10: yes | K10: WebXR/shared/equipment.js EQUIPMENT_BUDGET
A11: generatorTrailer | B11: equipment | C11: generatorTrailer | D11: 14 | E11: 1.9 x 2.41 x 4.54 | F11: doorL; doorR; controlPanel; eStop; wheels; jack; lights | G11: towable diesel generator | H11: 4 | I11: br-surface-supplied-dive-station-setup; cs-ventilation-and-air-monitoring-plan; le-crowd-barricade-and-show-stop-call; ut-night-storm-response-crew-and-portable-generator | J11: yes | K11: WebXR/shared/equipment.js EQUIPMENT_BUDGET
A12: lightTower | B12: equipment | C12: lightTower | D12: 17 | E12: 2.34 x 9.29 x 3.49 | F12: mast; mastUpper; lamps; outriggers; controlPanel; wheels; jack | G12: towable light tower, raised | H12: 1 | I12: le-crowd-barricade-and-show-stop-call | J12: yes | K12: WebXR/shared/equipment.js EQUIPMENT_BUDGET
A13: lightTower:stowed | B13: equipment | C13: lightTower | D13: 17 | E13: 1.58 x 1.77 x 4.81 | F13: mast; mastUpper; lamps; outriggers; controlPanel; wheels; jack | G13: towable light tower, stowed for tow | H13: 1 | I13: le-crowd-barricade-and-show-stop-call | J13: yes | K13: WebXR/shared/equipment.js EQUIPMENT_BUDGET
... A52: ambulance | B52: vehicle | C52: ambulance | D52: 25 | E52: 2.62 x 3.13 x 7.06 | F52: doorL; doorR; doorSide; doorRearL; doorRearR; compartments; warningLights; wheels; mirrorL; mirrorR; lights | G52: Type III, generic markings, rear chevrons | H52: 2 | I52: firefighter-rehab-sector; hz-decon-corridor-for-a-mass-casualty-drill | J52: yes | K52: WebXR/shared/fleet.js FLEET_BUDGET
A53: fireEngine | B53: vehicle | C53: fireEngine | D53: 28 | E53: 3.2 x 3.23 x 10.25 | F53: doorL; doorR; doorCrewL; doorCrewR; pumpPanel; pumpControls; hoseBed; ladder; compartments; warningLights; wheels; mirrorL; mirrorR; lights | G53: pumper: pump panel, hose bed, roof ladders | H53: 0 | J53: yes | K53: WebXR/shared/fleet.js FLEET_BUDGET
A54: bucketTruck | B54: vehicle | C54: bucketTruck | D54: 32 | E54: 3.3 x 3.44 x 9.6 | F54: doorL; doorR; mirrorL; mirrorR; wheels; lights; turret; boom; boomUpper; bucket; outriggers; compartments; controls | G54: insulated aerial device, articulated turret-boom-bucket | H54: 0 | J54: yes | K54: WebXR/shared/fleet.js FLEET_BUDGET
A55: busTransit | B55: vehicle | C55: busTransit | D55: 16 | E55: 3.3 x 3.26 x 12.42 | F55: doorFront; doorRear; destinationSign; wheels; mirrorL; mirrorR; lights | G55: 40 ft low-floor | H55: 2 | I55: bus-depot-lift; tr-wheelchair-lift-and-securement-on-a-bus | J55: yes | K55: WebXR/shared/fleet.js FLEET_BUDGET
A56: schoolBus | B56: vehicle | C56: schoolBus | D56: 33 | E56: 3.16 x 3.1 x 10.79 | F56: doorEntry; doorRear; mirrorL; mirrorR; crossviewMirror; wheels; lights; stopArm; crossingGate; warningLights | G56: Type C conventional, 35 ft, 8-way warning lights, stop arm and crossing gate | H56: 1 | I56: ed-bus-pretrip-and-loading-zone | J56: yes | K56: WebXR/shared/fleet.js FLEET_BUDGET
A57: forkliftCounterbalance | B57: vehicle | C57: forkliftCounterbalance | D57: 21 | E57: 1.12 x 2.28 x 3.57 | F57: mast; innerMast; carriage; forks; overheadGuard; counterweight; lpgTank; seat; controls; beacon; wheels; lights | G57: 5,000 lb LPG counterbalance | H57: 9 | I57: drive-backing-serpentine-and-alley-dock; drive-light-vehicle-fleet-and-forklift-course; forklift-dock; hz-drum-staging-and-compatibility-segregation; ml-mail-handler-forklift-and-container-dock; tdl-trailer-loading-and-dock-plate; tw-battery-change-and-charging-bay-safety; tw-cold-storage-ppe-and-rotation; tw-dock-leveler-and-trailer-restraint-check | J57: yes | K57: WebXR/shared/fleet.js FLEET_BUDGET
A58: yardHustler | B58: vehicle | C58: yardHustler | D58: 19 | E58: 2.91 x 3.43 x 5.61 | F58: doorL; doorRear; mirrorL; mirrorR; wheels; fifthWheel; gladHandService; gladHandEmergency; beacon; lights | G58: terminal tractor, lifting fifth wheel | H58: 4 | I58: ml-delivery-van-pretrip-and-route-loading; po-yard-hostler-and-pedestrian-separation; tdl-pretrip-inspection; tdl-trailer-loading-and-dock-plate | J58: yes | K58: WebXR/shared/fleet.js FLEET_BUDGET
A59: workboat | B59: boat | C59: workboat | D59: 16 | E59: 3.15 x 3.45 x 8.18 | F59: wheelhouseDoor; outboards; davit; navLights; portLight; starboardLight; mastheadLight | G59: 7.6 m aluminium workboat | H59: 16 | I59: br-benthic-grab-and-invertebrate-sorting; br-boom-towing-between-two-vessels; br-cold-water-immersion-and-mob-recovery; br-dive-site-hazard-assessment-and-jsa; br-dive-tender-and-umbilical-management; br-dredge-material-screening-and-disposal-decision; br-hyperbaric-chamber-standby; br-marine-mammal-observer-during-pile-driving; br-sediment-chain-of-custody-and-lab-prep; br-surface-supplied-dive-station-setup; br-turbidity-curtain-deployment; br-vhf-and-navigation-in-a-work-zone; br-water-quality-sonde-calibration-and-deploy; br-workboat-crane-lift-from-water; cd-rov-launch-recovery-and-tether-management; me-water-column-sampling-from-a-small-boat | J59: yes | K59: WebXR/shared/fleet.js FLEET_BUDGET
A60: motorYacht | B60: boat | C60: motorYacht | D60: 35 | E60: 6.72 x 8.01 x 24.23 | F60: saloonDoor; helm; bowCleats; springCleats; sternCleats; fuelFill; shorePowerInlet; engineHatch; davit; tender; fenders; lifeRing; navLights; portLight; starboardLight; mastheadLight; sternLight | G60: 24 m motor yacht: flybridge, swim platform, tender in a davit, shore-power inlet | H60: 6 | I60: yc-fuel-dock-transfer-and-spill-kit; yc-line-handling-and-docking-in-crosswind; yc-man-overboard-recovery-drill; yc-pre-departure-safety-briefing-and-guest-count; yc-shore-power-connection-and-in-water-electrical-safety; yc-tender-launch-and-guest-transfer | J60: yes | K60: WebXR/shared/fleet.js FLEET_BUDGET
A61: yachtTender | B61: boat | C61: yachtTender | D61: 15 | E61: 1.89 x 1.52 x 4.55 | F61: outboard; killCord; console; bowEye; sternCleat; fuelTank; navLight | G61: 4.2 m rigid inflatable tender with an outboard and a kill-cord | H61: 1 | I61: yc-tender-launch-and-guest-transfer | J61: yes | K61: WebXR/shared/fleet.js FLEET_BUDGET
A62: skiff | B62: boat | C62: skiff | D62: 17 | E62: 2.11 x 1.79 x 5.69 | F62: outboard; console; killSwitch; bowCleat; sternCleat; navLights; portLight; starboardLight; sternLight | G62: 5.2 m aluminium centre-console skiff | H62: 13 | I62: br-beach-seine-fish-survey-and-handling; br-bird-nesting-buffer-and-work-window; br-boom-towing-between-two-vessels; br-cold-water-immersion-and-mob-recovery; br-debris-skimmer-vessel-operations; br-derelict-vessel-salvage-rigging; br-drone-shoreline-survey; br-marine-mammal-observer-during-pile-driving; br-vhf-and-navigation-in-a-work-zone; br-volunteer-cleanup-day-safety-lead; cd-scientific-scuba-buddy-check-and-lost-buddy-drill; me-eelgrass-seed-collection-and-nursery; me-oyster-reef-monitoring-and-settlement-tiles | J62: yes | K62: WebXR/shared/fleet.js FLEET_BUDGET
A63: deckBarge | B63: boat | C63: deckBarge | D63: 13 | E63: 6.24 x 2.7 x 16 | F63: bitts; ladder | G63: 16 m flat steel deck barge, raked ends | H63: 2 | I63: br-barge-loading-of-contaminated-sediment; br-vhf-and-navigation-in-a-work-zone | J63: yes | K63: WebXR/shared/fleet.js FLEET_BUDGET
A64: deckBarge:hopper | B64: boat | C64: deckBarge | D64: 16 | E64: 6.24 x 3.1 x 16 | F64: bitts; ladder; coaming; liner; load | G64: deck barge with a lined sediment hopper | H64: 2 | I64: br-barge-loading-of-contaminated-sediment; br-vhf-and-navigation-in-a-work-zone | J64: yes | K64: WebXR/shared/fleet.js FLEET_BUDGET
A65: salvageCraneBarge | B65: boat | C65: salvageCraneBarge | D65: 30 | E65: 7.24 x 13.59 x 18 | F65: house; boom; hook; hoistLine; counterweight; cabDoor; spuds; bitts; ladder | G65: 18 m spud barge with a revolving lattice-boom crane | H65: 2 | I65: br-derelict-vessel-salvage-rigging; br-marine-mammal-observer-during-pile-driving | J65: yes | K65: WebXR/shared/fleet.js FLEET_BUDGET
A66: skimmerVessel | B66: boat | C66: skimmerVessel | D66: 20 | E66: 4.22 x 4.1 x 12.21 | F66: conveyor; basket; sweepArms; tankHatch; wheelhouseDoor; navLights; portLight; starboardLight; mastheadLight | G66: 11 m catamaran debris and oil skimmer | H66: 1 | I66: br-debris-skimmer-vessel-operations | J66: yes | K66: WebXR/shared/fleet.js FLEET_BUDGET
... A70: rov | B70: boat | C70: rov | D70: 9 | E70: 0.62 x 0.55 x 1.01 | F70: thrusters; camera; lights; manipulator; tetherPoint | G70: observation-class ROV, four thrusters, camera dome, manipulator | H70: 1 | I70: cd-rov-launch-recovery-and-tether-management | J70: yes | K70: WebXR/shared/fleet.js FLEET_BUDGET
A71: jerseyBarrier | B71: prop | C71: jerseyBarrier | D71: 1 | E71: 0.61 x 0.81 x 3.05 | G71: concrete F-shape traffic barrier, 10 ft run | H71: 0 | J71: no | K71: WebXR/shared/props.js PROPS_BUDGET
A72: waterBarrier | B72: prop | C72: waterBarrier | D72: 2 | E72: 0.5 x 0.79 x 1.83 | G72: plastic water/sand-filled lane barrier | H72: 1 | I72: md-location-shoot-traffic-control-and-heat-hydration | J72: no | K72: WebXR/shared/props.js PROPS_BUDGET
A73: coneCluster | B73: prop | C73: coneCluster | D73: 9 | E73: 1 x 0.71 x 0.84 | G73: three traffic cones in a triangle | H73: 1 | I73: md-location-shoot-traffic-control-and-heat-hydration | J73: no | K73: WebXR/shared/props.js PROPS_BUDGET
A74: lightMast | B74: prop | C74: lightMast | D74: 10 | E74: 1.3 x 9 x 0.5 | F74: lamps | G74: fixed site light mast, four heads, lit at night | H74: 0 | J74: no | K74: WebXR/shared/props.js PROPS_BUDGET
A75: portableToilet | B75: prop | C75: portableToilet | D75: 4 | E75: 1.26 x 2.32 x 1.26 | F75: door | G75: single-unit portable toilet | H75: 0 | J75: no | K75: WebXR/shared/props.js PROPS_BUDGET
A76: siteOffice | B76: prop | C76: siteOffice | D76: 6 | E76: 2.45 x 3.1 x 6.49 | F76: door | G76: 20 ft portable site office | H76: 2 | I76: cd-dive-records-and-incident-review; md-location-shoot-traffic-control-and-heat-hydration | J76: no | K76: WebXR/shared/props.js PROPS_BUDGET
A77: dumpster | B77: prop | C77: dumpster | D77: 4 | E77: 1.37 x 1.26 x 1.83 | F77: lidL; lidR | G77: front-load construction dumpster | H77: 4 | I77: op-equipment-daily-walkaround-and-fluids; op-excavator-trench-and-utility-locate; op-loader-truck-loading-and-blind-spots; tw-conveyor-jam-clearing-and-loto | J77: no | K77: WebXR/shared/props.js PROPS_BUDGET
A78: scaffoldTower | B78: prop | C78: scaffoldTower | D78: 14 | E78: 1.4 x 4 x 1.4 | G78: two-lift scaffold tower with platform and guardrail | H78: 1 | I78: av-hangar-jacking-and-stands | J78: no | K78: WebXR/shared/props.js PROPS_BUDGET
A79: palletStack | B79: prop | C79: palletStack | D79: 4 | E79: 1.04 x 1.7 x 1.24 | G79: three loaded pallets under shrink film | H79: 12 | I79: av-baggage-belt-loader-and-hold-loading; ml-flat-sorter-guarding-and-lockout; ml-mail-handler-forklift-and-container-dock; ml-parcel-sorter-conveyor-jam-and-loto; ml-suspicious-package-protocol; tw-amr-traffic-zone-entry-and-lockout; tw-cold-storage-ppe-and-rotation; tw-conveyor-jam-clearing-and-loto; tw-dock-leveler-and-trailer-restraint-check; tw-high-bay-order-picker-fall-protection; tw-palletizer-cell-fenced-access-permit; tw-pick-to-light-ergonomics-and-rotation | J79: no | K79: WebXR/shared/props.js PROPS_BUDGET
A80: cableSpool | B80: prop | C80: cableSpool | D80: 3 | E80: 0.9 x 1.5 x 1.5 | G80: wound cable reel, standing on its rim | H80: 3 | I80: op-compactor-lift-thickness-and-edge; op-dozer-slope-work-and-rollover-protection; op-excavator-trench-and-utility-locate | J80: no | K80: WebXR/shared/props.js PROPS_BUDGET
A81: fireHydrant | B81: prop | C81: fireHydrant | D81: 6 | E81: 0.38 x 0.78 x 0.46 | G81: dry-barrel fire hydrant | H81: 1 | I81: ut-hydrant-flow-test-and-flushing-with-traffic-control | J81: no | K81: WebXR/shared/props.js PROPS_BUDGET
...

Sheet Vehicles and Boats
A1: name | B1: family | C1: build | D1: meshes | E1: footprint | F1: description | G1: stationCount | H1: unity | I1: source
A2: semiTractor | B2: vehicle | C2: semiTractor | D2: 24 | E2: 3.02 x 3.95 x 6.86 | F2: Class 8 conventional tractor, tandem drive. | G2: 2 | H2: yes | I2: WebXR/shared/fleet.js semiTractor() doc comment; FLEET_BUDGET
A3: semiTractor:sleeper | B3: vehicle | C3: semiTractor | D3: 24 | E3: 3.02 x 4 x 8.66 | F3: Class 8 conventional tractor, tandem drive. | G3: 2 | H3: yes | I3: WebXR/shared/fleet.js semiTractor() doc comment; FLEET_BUDGET
A4: trailer:dryVan | B4: vehicle | C4: trailer | D4: 14 | E4: 2.63 x 4.11 x 16.27 | F4: Semi-trailer. | G4: 3 | H4: yes | I4: WebXR/shared/fleet.js trailer() doc comment; FLEET_BUDGET
A5: trailer:flatbed | B5: vehicle | C5: trailer | D5: 13 | E5: 2.66 x 1.53 x 14.69 | F5: Semi-trailer. | G5: 3 | H5: yes | I5: WebXR/shared/fleet.js trailer() doc comment; FLEET_BUDGET
A6: trailer:reefer | B6: vehicle | C6: trailer | D6: 17 | E6: 2.63 x 4.11 x 16.7 | F6: Semi-trailer. | G6: 3 | H6: yes | I6: WebXR/shared/fleet.js trailer() doc comment; FLEET_BUDGET
A7: trailer:tanker | B7: vehicle | C7: trailer | D7: 14 | E7: 2.63 x 3.26 x 12.94 | F7: Semi-trailer. | G7: 3 | H7: yes | I7: WebXR/shared/fleet.js trailer() doc comment; FLEET_BUDGET
A8: trailer:pup | B8: vehicle | C8: trailer | D8: 13 | E8: 2.63 x 4.11 x 8.65 | F8: Semi-trailer. | G8: 3 | H8: yes | I8: WebXR/shared/fleet.js trailer() doc comment; FLEET_BUDGET
A9: tractorTrailer | B9: vehicle | C9: tractorTrailer | D9: 38 | E9: 3.02 x 4.11 x 20.71 | F9: A coupled tractor-trailer: `opts.cab` and `opts.trailer` pick the pieces, the trailer's kingpin sits over the fifth wheel. | G9: 7 | H9: yes | I9: WebXR/shared/fleet.js tractorTrailer() doc comment; FLEET_BUDGET
A10: boxTruck | B10: vehicle | C10: boxTruck | D10: 21 | E10: 3.02 x 4.05 x 10 | F10: Class 6 box truck: conventional cab and a 26 ft dry box with a roll-up rear door. | G10: 3 | H10: yes | I10: WebXR/shared/fleet.js boxTruck() doc comment; FLEET_BUDGET
A11: pickup | B11: vehicle | C11: pickup | D11: 17 | E11: 2.39 x 1.93 x 5.92 | F11: Full-size crew-cab pickup, 5.9 m × 2.03 m × 1.95 m, 1.65 m bed. | G11: 11 | H11: yes | I11: WebXR/shared/fleet.js pickup() doc comment; FLEET_BUDGET
A12: sedan | B12: vehicle | C12: sedan | D12: 17 | E12: 2.23 x 1.45 x 4.92 | F12: Mid-size sedan, 4.9 m × 1.85 m × 1.45 m. | G12: 10 | H12: yes | I12: WebXR/shared/fleet.js sedan() doc comment; FLEET_BUDGET
A13: cargoVan | B13: vehicle | C13: cargoVan | D13: 18 | E13: 2.41 x 2.72 x 5.99 | F13: High-roof full-size cargo van, 5.93 m × 2.05 m × 2.75 m. | G13: 5 | H13: yes | I13: WebXR/shared/fleet.js cargoVan() doc comment; FLEET_BUDGET
... A33: rov | B33: boat | C33: rov | D33: 9 | E33: 0.62 x 0.55 x 1.01 | F33: Observation-class ROV: 0.9 m long, 0.62 m wide, 0.5 m tall, an open aluminium frame under a yellow syntactic-foam flotation block, a camera dome forward, two LED lamps beside it, four thrusters (two horizontal aft, two vertical), a single-function manipulator jaw forward-low and a tether termination on top. | G33: 1 | H33: yes | I33: WebXR/shared/fleet.js rov() doc comment; FLEET_BUDGET

Sheet Worlds
A1: name | B1: page | C1: bounds | D1: zones | E1: sites | F1: landmarks | G1: routes | H1: meshBudget | I1: quests | J1: eggs | K1: activities | L1: source
A2: Bay World | B2: WebXR/dist/bayworld.html | C2: x -1200..1200, z -800..800 | D2: 16 | E2: 50 | F2: 28 | G2: 15 roads | H2: 100-3600 | I2: 113 | J2: 34 | K2: 6 | L2: WebXR/shared/bayworld-data.js; WebXR/bayworld/js/quests-data.js
A3: The Deep | B3: WebXR/dist/underwater.html | C3: x -1000..1000, z -700..700 | D3: 14 | E3: 32 | F3: 25 | G3: 17 lines | H3: 100-1400 | I3: 40 | J3: 24 | K3: 4 | L3: WebXR/shared/underwater-data.js; WebXR/underwater/js/dives-data.js
A4: Fairway Park | B4: WebXR/dist/fairway.html | C4: x -300..300, z -50..350 | D4: 8 | E4: 9 holes | G4: par 36 over 9 holes | H4: 130-900 | L4: WebXR/shared/fairway-data.js
A5: Bay Regatta | B5: WebXR/dist/regatta.html | C5: x -1200..1200, z -800..800 | D5: 4 | E5: 12 yachts | G5: 3 courses | K5: 5 | L5: WebXR/shared/yacht-fleet.js; WebXR/regatta/js/courses.js; WebXR/regatta/js/events.js; bounds from WebXR/shared/bayworld-data.js
A6: golden-gate-deck (scenic district) | B6: WebXR/dist/smartcity-x.html | H6: 120 | L6: WebXR/smartcity/js/districts.js DISTRICTS (plaza: false), SCENIC_BUDGET
A7: bay-underwater (scenic district) | B7: WebXR/dist/smartcity-x.html | H7: 120 | L7: WebXR/smartcity/js/districts.js DISTRICTS (plaza: false), SCENIC_BUDGET
A8: gym-court (scenic district) | B8: WebXR/dist/smartcity-x.html | H8: 120 | L8: WebXR/smartcity/js/districts.js DISTRICTS (plaza: false), SCENIC_BUDGET
A9: open-range (scenic district) | B9: WebXR/dist/smartcity-x.html | H9: 120 | L9: WebXR/smartcity/js/districts.js DISTRICTS (plaza: false), SCENIC_BUDGET
A10: fairway-park (scenic district) | B10: WebXR/dist/smartcity-x.html | H10: 120 | L10: WebXR/smartcity/js/districts.js DISTRICTS (plaza: false), SCENIC_BUDGET
A11: bay-world (scenic district) | B11: WebXR/dist/smartcity-x.html | H11: 120 | L11: WebXR/smartcity/js/districts.js DISTRICTS (plaza: false), SCENIC_BUDGET
A12: the-deep (scenic district) | B12: WebXR/dist/smartcity-x.html | H12: 120 | L12: WebXR/smartcity/js/districts.js DISTRICTS (plaza: false), SCENIC_BUDGET

Sheet UI Surfaces
A1: name | B1: path | C1: purpose | D1: inputModes | E1: hudPanelCount | F1: hudPanels | G1: source
A2: Break Room Arcade | B2: WebXR/dist/arcade.html | C2: The training platform's other Easter egg: a row of four retro cabinets in the crew break room, each an original 2D canvas game — a climbing platformer, a side-scrolling runner, a falling-block stacker and a lane-crossing dodger — with pixel art, a chiptune soundtrack and local high scores. | D2: flat; keyboard; touch; gamepad | E2: 1 | F2: hud-top | G2: WebXR/dist/arcade.html (<title>, meta description, input listeners, element ids)
A3: Bay Atlas | B3: WebXR/dist/atlas.html | C3: Every Bay World training site and landmark with its programmes and deep links, over a map: drawn from the world's own data, or over a real-world Mapbox map when you supply your own token. | D3: flat; keyboard; touch | E3: 0 | G3: WebXR/dist/atlas.html (<title>, meta description, input listeners, element ids)
A4: Bay World | B4: WebXR/dist/bayworld.html | C4: A free-roam open-world city on the training platform: walk or drive anywhere, day and night, traffic and weather, a map, and missions that launch the platform's real training stations. | D4: flat; keyboard; touch; gamepad | E4: 14 | F4: hud; hud-buttons; hud-clock; hud-credits; hud-map-btn; hud-minimap; hud-objective; hud-phone; hud-prompt; hud-radio-btn; hud-reputation; hud-stats; hud-weather; hud-zone | G4: WebXR/dist/bayworld.html (<title>, meta description, input listeners, element ids)
A5: Fairway Park | B5: WebXR/dist/fairway.html | C5: An original nine-hole golf course and an outdoor sports facility on the training platform: stroke play with a timed swing meter, real scoring, and a groundskeeper's log that scores course care alongside it. | D5: flat; keyboard; touch; gamepad | E5: 8 | F5: hud; hud-care; hud-clubs; hud-hole; hud-lie; hud-meter; hud-score; hud-wind | G5: WebXR/dist/fairway.html (<title>, meta description, input listeners, element ids)
A6: Holodeck ~ Speak a Simulation Into Existence | B6: WebXR/dist/holodeck.html | C6: Toolbox Talk Bingo | D6: flat; vr; keyboard; touch; gamepad; hands | E6: 0 | G6: WebXR/dist/holodeck.html (<title>, meta description, input listeners, element ids)
A7: Training Simulators — every station | B7: WebXR/dist/index.html | C7: Every station in the training network on one page: 633 AR/VR simulators across 20 categories, with a deep link to each one. | D7: flat; keyboard | E7: 0 | G7: WebXR/dist/index.html (<title>, meta description, input listeners, element ids)
A8: Instructor Console | B8: WebXR/dist/instructor-console.html | C8: A live view of the training sessions running on this machine — or through a relay — with the content and interaction controls for each learner: where they are, what they have hit, the station's own interruptions, its weather and device profile, and the programme they are on. | D8: flat; keyboard; touch | E8: 5 | F8: panel; panel-ints; panel-steps; panel-where; panel-who | G8: WebXR/dist/instructor-console.html (<title>, meta description, input listeners, element ids)
A9: Night Highway Circuit | B9: WebXR/dist/race.html | C9: The training platform's Easter egg: an arcade racer on ten original courses (plus a Mirror class and a Battle Arena), driven in the platform's own fleet. | D9: flat; keyboard; touch; gamepad | E9: 1 | F9: huds | G9: WebXR/dist/race.html (<title>, meta description, input listeners, element ids)
A10: Bay Regatta | B10: WebXR/dist/regatta.html | C10: A fleet of twelve motor yachts on Bay World's water: hosted events with a safety briefing before every cast-off, three original race courses against the fleet, scored on marks, the no-wake zone, right of way and a clean docking. | D10: flat; keyboard; touch; gamepad | E10: 10 | F10: hud; hud-checks; hud-course; hud-course-map; hud-helm; hud-next; hud-speed; hud-time; hud-warn; hud-yacht | G10: WebXR/dist/regatta.html (<title>, meta description, input listeners, element ids)
A11: SmartCiti.X ~VR Simulators | B11: WebXR/dist/smartcity-x.html | C11: Training Activity Record | D11: flat; vr; ar; keyboard; touch; gamepad; hands | E11: 0 | G11: WebXR/dist/smartcity-x.html (<title>, meta description, input listeners, element ids)
A12: Trade Skills Simulator | B12: WebXR/dist/trade-skills-simulator.html | C12: Trade Skills Simulator | D12: flat; vr; keyboard; touch; gamepad; hands | E12: 17 | F12: hud-combo; hud-count; hud-cue; hud-feedback; hud-fill; hud-gesture; hud-hint; hud-metrics; hud-mission; hud-objective; hud-progress; hud-rail; hud-room; hud-score; hud-step; hud-timer; hud-track | G12: WebXR/dist/trade-skills-simulator.html (<title>, meta description, input listeners, element ids)
